sdbf:03:131:fdf75127393924a30ce4a480ad524bd09ada956795d5150942bb779ceda6ddc2/usr/lib64/python3.4/xml/sax/__pycache__/_exceptions.cpython-34.pyo:5683:sha1:256:5:7ff:160:1:87:gAQXAQQAgAASAAAABJmCJFBIBAAAAAEYAKpQoEgAWABCIacDBACgABFChB0TCAFwIoSAACyAAgCAIGFIRmFYzAQEACAwDEKIMECAoMAIAA0CAE0IEgIQoCDKzATgQUQAAghAGRAgDAFCAEAKIECAkYCQBgDG4ABAiBECDCAABTIoAAPQFpAJICYAEkOCCISiIABLAAACBUAEBASCYAUDgIAAYCEACMg0KIaWgBAIgUAJRUFBAQEIxADAAgCACICAUAACQAAAMSWAIKACEYMAIIgBIoEMAOSII7IAIIDBSCiIACM8CBgqEkggYABAAEUAgAhgEQADEKAAIYACAIAKIA==
