sdbf:03:112:fdf75127393924a30ce4a480ad524bd09ada956795d5150942bb779ceda6ddc2/usr/lib64/python3.4/lib2to3/fixes/fix_urllib.py:8384:sha1:256:5:7ff:160:1:150:RQrIJBwAsZaBBDADggCAFMAHHAAYhSBBAcFQgYGwNHQMCAowwRYEpoKggXSnEHQAUcsSgFeogEgCogMADQMYzCligyspXBmgIERBGuBIIyAsLmABHJgOAAQTRCAMABCQJBZPKMuHYQgsQIAUoSKbsBUQY3FDFCIVOBFACSYQMAcoQCglgACkxAAcIYpYAIwbBDHASgFkBAoRAU4opkQmEnQKEaGSIRFNgYgwoKRRKIemva4AgJQWMjZdhEgCMBDALECaCYTgIEA+RilZUozAggEagB4nIwmgBFBHnPDAiopSEGoBWsogiT6KXATKMAAAQUQgRggAiCAAx5si4mOKPQ==
