sdbf:03:136:fdf75127393924a30ce4a480ad524bd09ada956795d5150942bb779ceda6ddc2/usr/lib64/python3.4/lib2to3/fixes/__pycache__/fix_except.cpython-34.pyo:3041:sha1:256:5:7ff:160:1:55:EAgQECIImBAhACgAAEKgIAkBgAEAACABAICAEBhEBAxAQAAhAAQQAAAEAAACAgAAABAQGAQAoGACAQAiEiIACkgIEoEcoAAgCABqAABABBBAAABABAAEBADAAiABAAEAAA4QIAAGAgAAAwQAAEABtAAElhgAIABIIABABgCRgAEQJFoAAgAEAAAMACAIAAAAAAQIFAMCRAIACQAQQEAGQDAAOIAAhAgEBEAAZAAABBQIKASBABQARgAKQBCgAADBgAAAABAYACAABIAAAAAABBEIAAKAigQAACIBBAiJAJgAAI4AAAAAIAAEkEAAEBAACAAIAAICEAIAAAEAABGYQA==
