sdbf:03:137:fdf75127393924a30ce4a480ad524bd09ada956795d5150942bb779ceda6ddc2/usr/lib64/python3.4/lib2to3/fixes/__pycache__/fix_sys_exc.cpython-34.pyo:1477:sha1:256:5:7ff:160:1:22:AAHAAoAAAAAAAAAAACAEAAAQAgAAAAABAAgAAAIAAAAAAAAABAACAAAAAAAAAIAAAAAAkAAAAAAAACgAAAAAIAAAAAIQIAAAAAIECAEAEEAEAAAAAIAAAQAAEAAQgAMAAAEAACAAiCAAAQgBAAEAAAAAIAAAAAAIAAAAAAAABQCAAEAAgAAAAAAACCIQAAAAMAAAACQAAAAARgABAAAAAAACAAAAAAACCAARAAQAAABCAAAgAAIBIAAAAAAAAMAQAAAAAAABAARiABAAAAAAAEAAAAAAAAAAAAIAIgAAQAAAAEgAAIISlFAABACAAIAAAAAAAAAAAAAQICAAAAAgCA==
