sdbf:03:138:fdf75127393924a30ce4a480ad524bd09ada956795d5150942bb779ceda6ddc2/usr/lib/python3.4/site-packages/dnf/__pycache__/exceptions.cpython-34.pyo:5469:sha1:256:5:7ff:160:1:73:MICAACSAAACJEAABFgAgAEAMQABKCEAABhgDRODIZAhAKAQAAEAoIjEApAIQASQAIDNAQEIKhMAAAgCAUFZQDCEFAQIEAQkBJAhIDAhAAFhAQcBEAAJAQIAICBAUAEAQACABCFAERFSCMAEACAUAFQCIAgEQGADRQACKAAIQBBgQhAAASAQAEBAAAACgKBMIAAIgBAAAhkAEURcAaBAQEBBAAwCQYEAQCEiQowAgUgEoQA0GAgQAZAQAAwhiAhEEABFgCDgAogA1AEgABiAgQEADBEABCCAQCCGABAQCQASEFACAEFA0AoAIAQAgIAEcBRAAgAACAAWARIBAAQURCQ==
