sdbf:03:123:fdf75127393924a30ce4a480ad524bd09ada956795d5150942bb779ceda6ddc2/usr/lib64/python3.4/__pycache__/tracemalloc.cpython-34.pyo:17117:sha1:256:5:7ff:160:2:109:tDEEusGoBoBQKgLAAQYCJEAIJDTpQgmcNjBcZAEobHpGjMEZKEQIAInlVebIJdj1IIvG0CQhoMRGEIKCJCAx484fMgpJBIUfmIx5O4K5gVmphAAPxgmpkEhhGrJJDC4CJ2gghgAMJYCo01c+gcHoEBEADx0BhREtERN4yEiAAsZIJFaQM0QjZRQjpDeLO2pEmCIEmnUxxCACsCQBIL5IEGFIZkECAAsyIgoACSURC0UIAFhlELUARdwhKR8rCEaIkYKxREdIgQjGcCgERFsAMiglMAxEJCQyRJwyBkRYKjEESAkIAyZDQEyykAAYiCGQzCExCREEQoGkQQi+YoBSTCAQrApQJACEDQQYYHgAgAAAJRAUlAvGMqHQAVOFskFAARgAALACAAgQMiJAEiiEkAISQDgQEoCgARGUAgQAYI0FCMFQUQIEACgELhAIMDAEBJACBChYkABBDSJyZgJAkGCRwiBABJBUIpEQIqAAGpQARSXRABSBmADAmgHEA4QAr4IAgSDQSQABAgYAEBhQAAYkZwYpEhNFICBWUAJuAMOEdIQAEAwkBgFCo4mASgAoSBkUkRBAAlEQJSFJAYACCBECiwRIxAMggAOEhggACwBIQAhEVCAkpCJgAGgCASoAEyx5hAUdREACEBDAEABiIABguCACMoAgiCAQQsbQjVE=
